Workbook

Sheet Huong dan
A2: Đề tài: Hệ thống quản lý giao hàng (ASP.NET Core 8, MySQL) | Thành viên: Trần Phương Hạo | 27 story, 106 điểm, 6 sprint x 14 ngày
A4: Các sheet trong file
A5: - Tong hop: số story, điểm, giờ, thời gian và năng lực của từng sprint.
A6: - WBS: cấu trúc 3 cấp (Sprint > Story PB01-PB27 > 3 task con: Phân tích và thiết kế, Lập trình, Kiểm thử), có điểm, giờ công, Start/Finish, người phụ trách, ưu tiên và tiêu chí chấp nhận.
A7: - Gantt: biểu đồ Gantt của toàn bộ WBS theo ngày (12 tuần).
A8: - Resources: danh sách thành viên.
A9: - Sprint 1 ... Sprint 6: burndown chart của từng sprint (đường Lý tưởng, Kế hoạch theo WBS, Thực tế).
A11: Cách cập nhật burndown thực tế
A12: Mỗi ngày của sprint, điền số điểm còn lại vào cột 'Thực tế' (ô vàng) trong sheet Sprint tương ứng; biểu đồ tự cập nhật.
A14: Giả định (chỉnh ở đầu sheet WBS)
A15: - Ngày bắt đầu 26/10/2026; mỗi sprint 14 ngày theo đề bài; 8 giờ/ngày; làm việc T2-T6.
A16: - 4 giờ cho mỗi điểm; chia 20% thiết kế, 60% lập trình, 20% kiểm thử. Các con số này là ước lượng, không có trong backlog.
... A18: - File kế hoạch cùng nội dung ở dạng MS Project XML (GiaoHang_KeHoach_DuAn.xml) đã mở được bằng ProjectLibre.

Sheet Tong hop
A1: TỔNG HỢP KẾ HOẠCH 6 SPRINT
A3: Sprint | B3: Số story | C3: Điểm | D3: Giờ KH | E3: Bắt đầu | F3: Kết thúc (timebox) | G3: Xong theo KH | H3: Năng lực (giờ) | I3: Dư/thiếu (giờ)
A4: Sprint 1 | B4: =COUNTIFS(WBS!$D$6:$D$119,1,WBS!$B$6:$B$119,2) -> 3 | C4: =WBS!E6 -> 13 | D4: =WBS!F6 -> 52 | E4: =WBS!H6 -> 46321 | F4: =WBS!I6 -> 46334 | G4: =MAX(WBS!I7:I18) -> 46329 | H4: =NETWORKDAYS(E4,F4)*WBS!$F$2 -> 80 | I4: =H4-D4 -> 28
A5: Sprint 2 | B5: =COUNTIFS(WBS!$D$6:$D$119,2,WBS!$B$6:$B$119,2) -> 5 | C5: =WBS!E19 -> 19 | D5: =WBS!F19 -> 76 | E5: =WBS!H19 -> 46335 | F5: =WBS!I19 -> 46348 | G5: =MAX(WBS!I20:I39) -> 46346 | H5: =NETWORKDAYS(E5,F5)*WBS!$F$2 -> 80 | I5: =H5-D5 -> 4
A6: Sprint 3 | B6: =COUNTIFS(WBS!$D$6:$D$119,3,WBS!$B$6:$B$119,2) -> 6 | C6: =WBS!E40 -> 20 | D6: =WBS!F40 -> 80 | E6: =WBS!H40 -> 46349 | F6: =WBS!I40 -> 46362 | G6: =MAX(WBS!I41:I64) -> 46360 | H6: =NETWORKDAYS(E6,F6)*WBS!$F$2 -> 80 | I6: =H6-D6 -> 0
A7: Sprint 4 | B7: =COUNTIFS(WBS!$D$6:$D$119,4,WBS!$B$6:$B$119,2) -> 5 | C7: =WBS!E65 -> 19 | D7: =WBS!F65 -> 76 | E7: =WBS!H65 -> 46363 | F7: =WBS!I65 -> 46376 | G7: =MAX(WBS!I66:I85) -> 46374 | H7: =NETWORKDAYS(E7,F7)*WBS!$F$2 -> 80 | I7: =H7-D7 -> 4
A8: Sprint 5 | B8: =COUNTIFS(WBS!$D$6:$D$119,5,WBS!$B$6:$B$119,2) -> 3 | C8: =WBS!E86 -> 18 | D8: =WBS!F86 -> 72 | E8: =WBS!H86 -> 46377 | F8: =WBS!I86 -> 46390 | G8: =MAX(WBS!I87:I98) -> 46387 | H8: =NETWORKDAYS(E8,F8)*WBS!$F$2 -> 80 | I8: =H8-D8 -> 8
A9: Sprint 6 | B9: =COUNTIFS(WBS!$D$6:$D$119,6,WBS!$B$6:$B$119,2) -> 5 | C9: =WBS!E99 -> 17 | D9: =WBS!F99 -> 68 | E9: =WBS!H99 -> 46391 | F9: =WBS!I99 -> 46404 | G9: =MAX(WBS!I100:I119) -> 46401 | H9: =NETWORKDAYS(E9,F9)*WBS!$F$2 -> 80 | I9: =H9-D9 -> 12
A10: Tổng | B10: =SUM(B4:B9) -> 27 | C10: =SUM(C4:C9) -> 106 | D10: =SUM(D4:D9) -> 424 | H10: =SUM(H4:H9) -> 480 | I10: =SUM(I4:I9) -> 56

Sheet WBS
A1: WBS - HỆ THỐNG QUẢN LÝ GIAO HÀNG
A2: Ngày bắt đầu: | B2: 46321 | C2: Độ dài Sprint (ngày): | D2: 14 | E2: Giờ/ngày: | F2: 8
A3: Giờ/điểm: | B3: 4 | C3: % Thiết kế: | D3: 0.2 | E3: % Lập trình: | F3: 0.6 | G3: % Kiểm thử: | H3: =1-D3-F3 -> 0.2
A5: WBS | B5: Level | C5: Task Name | D5: Sprint | E5: Điểm | F5: Work (giờ) | G5: Duration (ngày) | H5: Start | I5: Finish | J5: Resource Names | K5: Ưu tiên | L5: Tiêu chí / ghi chú (từ Sprint backlog) | M5: Giờ lũy kế trước task (trong sprint)
A6: 1 | B6: 1 | C6: Sprint 1 | D6: 1 | E6: =SUMIFS(E7:E18,B7:B18,2) -> 13 | F6: =SUMIFS(F7:F18,B7:B18,2) -> 52 | G6: =ROUND(F6/$F$2,1) -> 6.5 | H6: =$B$2+$D$2*(D6-1) -> 46321 | I6: =H6+$D$2-1 -> 46334 | J6: Trần Phương Hạo
A7: 1.1 | B7: 2 | C7: PB01 - Khởi tạo dự án .NET 8 + MySQL | D7: 1 | E7: 5 | F7: =SUM(F8:F10) -> 20 | G7: =ROUND(F7/$F$2,1) -> 2.5 | H7: =MIN(H8:H10) -> 46321 | I7: =MAX(I8:I10) -> 46323 | J7: Trần Phương Hạo | K7: Must | L7: dotnet run chạy được; migration tạo CSDL MySQL (Pomelo); có README hướng dẫn chạy
A8: 1.1.1 | B8: 3 | C8: Phân tích và thiết kế PB01 | D8: 1 | F8: =$B$3*E7*$D$3 -> 4 | G8: =ROUND(F8/$F$2,2) -> 0.5 | H8: =WORKDAY($H$6,INT(M8/$F$2)) -> 46321 | I8: =WORKDAY($H$6,INT((M8+F8)/$F$2-0.000001)) -> 46321 | J8: Trần Phương Hạo | M8: =SUMIFS($F$6:$F7,$D$6:$D7,$D8,$B$6:$B7,3) -> 0
A9: 1.1.2 | B9: 3 | C9: Lập trình PB01 | D9: 1 | F9: =$B$3*E7*$F$3 -> 12 | G9: =ROUND(F9/$F$2,2) -> 1.5 | H9: =WORKDAY($H$6,INT(M9/$F$2)) -> 46321 | I9: =WORKDAY($H$6,INT((M9+F9)/$F$2-0.000001)) -> 46322 | J9: Trần Phương Hạo | M9: =SUMIFS($F$6:$F8,$D$6:$D8,$D9,$B$6:$B8,3) -> 4
A10: 1.1.3 | B10: 3 | C10: Kiểm thử PB01 | D10: 1 | F10: =$B$3*E7*$H$3 -> 4 | G10: =ROUND(F10/$F$2,2) -> 0.5 | H10: =WORKDAY($H$6,INT(M10/$F$2)) -> 46323 | I10: =WORKDAY($H$6,INT((M10+F10)/$F$2-0.000001)) -> 46323 | J10: Trần Phương Hạo | M10: =SUMIFS($F$6:$F9,$D$6:$D9,$D10,$B$6:$B9,3) -> 16
A11: 1.2 | B11: 2 | C11: PB02 - Đăng nhập và phân quyền theo vai trò | D11: 1 | E11: 5 | F11: =SUM(F12:F14) -> 20 | G11: =ROUND(F11/$F$2,1) -> 2.5 | H11: =MIN(H12:H14) -> 46323 | I11: =MAX(I12:I14) -> 46325 | J11: Trần Phương Hạo | K11: Must | L11: ASP.NET Core Identity; seed 4 vai trò + tài khoản mẫu; vào trang không đủ quyền bị chặn
A12: 1.2.1 | B12: 3 | C12: Phân tích và thiết kế PB02 | D12: 1 | F12: =$B$3*E11*$D$3 -> 4 | G12: =ROUND(F12/$F$2,2) -> 0.5 | H12: =WORKDAY($H$6,INT(M12/$F$2)) -> 46323 | I12: =WORKDAY($H$6,INT((M12+F12)/$F$2-0.000001)) -> 46323 | J12: Trần Phương Hạo | M12: =SUMIFS($F$6:$F11,$D$6:$D11,$D12,$B$6:$B11,3) -> 20
A13: 1.2.2 | B13: 3 | C13: Lập trình PB02 | D13: 1 | F13: =$B$3*E11*$F$3 -> 12 | G13: =ROUND(F13/$F$2,2) -> 1.5 | H13: =WORKDAY($H$6,INT(M13/$F$2)) -> 46324 | I13: =WORKDAY($H$6,INT((M13+F13)/$F$2-0.000001)) -> 46325 | J13: Trần Phương Hạo | M13: =SUMIFS($F$6:$F12,$D$6:$D12,$D13,$B$6:$B12,3) -> 24
A14: 1.2.3 | B14: 3 | C14: Kiểm thử PB02 | D14: 1 | F14: =$B$3*E11*$H$3 -> 4 | G14: =ROUND(F14/$F$2,2) -> 0.5 | H14: =WORKDAY($H$6,INT(M14/$F$2)) -> 46325 | I14: =WORKDAY($H$6,INT((M14+F14)/$F$2-0.000001)) -> 46325 | J14: Trần Phương Hạo | M14: =SUMIFS($F$6:$F13,$D$6:$D13,$D14,$B$6:$B13,3) -> 36
A15: 1.3 | B15: 2 | C15: PB03 - Quản lý tài khoản nhân viên | D15: 1 | E15: 3 | F15: =SUM(F16:F18) -> 12 | G15: =ROUND(F15/$F$2,1) -> 1.5 | H15: =MIN(H16:H18) -> 46328 | I15: =MAX(I16:I18) -> 46329 | J15: Trần Phương Hạo | K15: Must | L15: Admin thêm/sửa/khóa tài khoản; không cho tự khóa chính mình
A16: 1.3.1 | B16: 3 | C16: Phân tích và thiết kế PB03 | D16: 1 | F16: =$B$3*E15*$D$3 -> 2.4 | G16: =ROUND(F16/$F$2,2) -> 0.3 | H16: =WORKDAY($H$6,INT(M16/$F$2)) -> 46328 | I16: =WORKDAY($H$6,INT((M16+F16)/$F$2-0.000001)) -> 46328 | J16: Trần Phương Hạo | M16: =SUMIFS($F$6:$F15,$D$6:$D15,$D16,$B$6:$B15,3) -> 40
A17: 1.3.2 | B17: 3 | C17: Lập trình PB03 | D17: 1 | F17: =$B$3*E15*$F$3 -> 7.2 | G17: =ROUND(F17/$F$2,2) -> 0.9 | H17: =WORKDAY($H$6,INT(M17/$F$2)) -> 46328 | I17: =WORKDAY($H$6,INT((M17+F17)/$F$2-0.000001)) -> 46329 | J17: Trần Phương Hạo | M17: =SUMIFS($F$6:$F16,$D$6:$D16,$D17,$B$6:$B16,3) -> 42.4
A18: 1.3.3 | B18: 3 | C18: Kiểm thử PB03 | D18: 1 | F18: =$B$3*E15*$H$3 -> 2.4 | G18: =ROUND(F18/$F$2,2) -> 0.3 | H18: =WORKDAY($H$6,INT(M18/$F$2)) -> 46329 | I18: =WORKDAY($H$6,INT((M18+F18)/$F$2-0.000001)) -> 46329 | J18: Trần Phương Hạo | M18: =SUMIFS($F$6:$F17,$D$6:$D17,$D18,$B$6:$B17,3) -> 49.6
A19: 2 | B19: 1 | C19: Sprint 2 | D19: 2 | E19: =SUMIFS(E20:E39,B20:B39,2) -> 19 | F19: =SUMIFS(F20:F39,B20:B39,2) -> 76 | G19: =ROUND(F19/$F$2,1) -> 9.5 | H19: =$B$2+$D$2*(D19-1) -> 46335 | I19: =H19+$D$2-1 -> 46348 | J19: Trần Phương Hạo
A20: 2.1 | B20: 2 | C20: PB04 - Nhận mã đơn hàng từ website bán hàng (API) | D20: 2 | E20: 5 | F20: =SUM(F21:F23) -> 20 | G20: =ROUND(F20/$F$2,1) -> 2.5 | H20: =MIN(H21:H23) -> 46335 | I20: =MAX(I21:I23) -> 46337 | J20: Trần Phương Hạo | K20: Must | L20: POST /api/orders + API key; mã trùng/sai trả lỗi; đơn mới ở trạng thái Chưa nhận; test bằng Postman
A21: 2.1.1 | B21: 3 | C21: Phân tích và thiết kế PB04 | D21: 2 | F21: =$B$3*E20*$D$3 -> 4 | G21: =ROUND(F21/$F$2,2) -> 0.5 | H21: =WORKDAY($H$19,INT(M21/$F$2)) -> 46335 | I21: =WORKDAY($H$19,INT((M21+F21)/$F$2-0.000001)) -> 46335 | J21: Trần Phương Hạo | M21: =SUMIFS($F$6:$F20,$D$6:$D20,$D21,$B$6:$B20,3) -> 0
A22: 2.1.2 | B22: 3 | C22: Lập trình PB04 | D22: 2 | F22: =$B$3*E20*$F$3 -> 12 | G22: =ROUND(F22/$F$2,2) -> 1.5 | H22: =WORKDAY($H$19,INT(M22/$F$2)) -> 46335 | I22: =WORKDAY($H$19,INT((M22+F22)/$F$2-0.000001)) -> 46336 | J22: Trần Phương Hạo | M22: =SUMIFS($F$6:$F21,$D$6:$D21,$D22,$B$6:$B21,3) -> 4
A23: 2.1.3 | B23: 3 | C23: Kiểm thử PB04 | D23: 2 | F23: =$B$3*E20*$H$3 -> 4 | G23: =ROUND(F23/$F$2,2) -> 0.5 | H23: =WORKDAY($H$19,INT(M23/$F$2)) -> 46337 | I23: =WORKDAY($H$19,INT((M23+F23)/$F$2-0.000001)) -> 46337 | J23: Trần Phương Hạo | M23: =SUMIFS($F$6:$F22,$D$6:$D22,$D23,$B$6:$B22,3) -> 16
A24: 2.2 | B24: 2 | C24: PB05 - Gửi yêu cầu giao hàng đến nhận hàng từ công ty | D24: 2 | E24: 3 | F24: =SUM(F25:F27) -> 12 | G24: =ROUND(F24/$F$2,1) -> 1.5 | H24: =MIN(H25:H27) -> 46337 | I24: =MAX(I25:I27) -> 46338 | J24: Trần Phương Hạo | K24: Must | L24: Danh sách đơn Chưa nhận; chọn nhân viên đi lấy; lưu thời điểm và người gửi yêu cầu
A25: 2.2.1 | B25: 3 | C25: Phân tích và thiết kế PB05 | D25: 2 | F25: =$B$3*E24*$D$3 -> 2.4 | G25: =ROUND(F25/$F$2,2) -> 0.3 | H25: =WORKDAY($H$19,INT(M25/$F$2)) -> 46337 | I25: =WORKDAY($H$19,INT((M25+F25)/$F$2-0.000001)) -> 46337 | J25: Trần Phương Hạo | M25: =SUMIFS($F$6:$F24,$D$6:$D24,$D25,$B$6:$B24,3) -> 20
A26: 2.2.2 | B26: 3 | C26: Lập trình PB05 | D26: 2 | F26: =$B$3*E24*$F$3 -> 7.2 | G26: =ROUND(F26/$F$2,2) -> 0.9 | H26: =WORKDAY($H$19,INT(M26/$F$2)) -> 46337 | I26: =WORKDAY($H$19,INT((M26+F26)/$F$2-0.000001)) -> 46338 | J26: Trần Phương Hạo | M26: =SUMIFS($F$6:$F25,$D$6:$D25,$D26,$B$6:$B25,3) -> 22.4
A27: 2.2.3 | B27: 3 | C27: Kiểm thử PB05 | D27: 2 | F27: =$B$3*E24*$H$3 -> 2.4 | G27: =ROUND(F27/$F$2,2) -> 0.3 | H27: =WORKDAY($H$19,INT(M27/$F$2)) -> 46338 | I27: =WORKDAY($H$19,INT((M27+F27)/$F$2-0.000001)) -> 46338 | J27: Trần Phương Hạo | M27: =SUMIFS($F$6:$F26,$D$6:$D26,$D27,$B$6:$B26,3) -> 29.6
A28: 2.3 | B28: 2 | C28: PB06 - Cập nhật trạng thái đơn hàng tuần tự | D28: 2 | E28: 3 | F28: =SUM(F29:F31) -> 12 | G28: =ROUND(F28/$F$2,1) -> 1.5 | H28: =MIN(H29:H31) -> 46339 | I28: =MAX(I29:I31) -> 46342 | J28: Trần Phương Hạo | K28: Must | L28: Không nhảy cóc/lùi trạng thái; lưu lịch sử người đổi, thời gian; dùng chung cho các story sau
A29: 2.3.1 | B29: 3 | C29: Phân tích và thiết kế PB06 | D29: 2 | F29: =$B$3*E28*$D$3 -> 2.4 | G29: =ROUND(F29/$F$2,2) -> 0.3 | H29: =WORKDAY($H$19,INT(M29/$F$2)) -> 46339 | I29: =WORKDAY($H$19,INT((M29+F29)/$F$2-0.000001)) -> 46339 | J29: Trần Phương Hạo | M29: =SUMIFS($F$6:$F28,$D$6:$D28,$D29,$B$6:$B28,3) -> 32
A30: 2.3.2 | B30: 3 | C30: Lập trình PB06 | D30: 2 | F30: =$B$3*E28*$F$3 -> 7.2 | G30: =ROUND(F30/$F$2,2) -> 0.9 | H30: =WORKDAY($H$19,INT(M30/$F$2)) -> 46339 | I30: =WORKDAY($H$19,INT((M30+F30)/$F$2-0.000001)) -> 46342 | J30: Trần Phương Hạo | M30: =SUMIFS($F$6:$F29,$D$6:$D29,$D30,$B$6:$B29,3) -> 34.4
A31: 2.3.3 | B31: 3 | C31: Kiểm thử PB06 | D31: 2 | F31: =$B$3*E28*$H$3 -> 2.4 | G31: =ROUND(F31/$F$2,2) -> 0.3 | H31: =WORKDAY($H$19,INT(M31/$F$2)) -> 46342 | I31: =WORKDAY($H$19,INT((M31+F31)/$F$2-0.000001)) -> 46342 | J31: Trần Phương Hạo | M31: =SUMIFS($F$6:$F30,$D$6:$D30,$D31,$B$6:$B30,3) -> 41.6
A32: 2.4 | B32: 2 | C32: PB07 - Quản lý bảng báo giá | D32: 2 | E32: 3 | F32: =SUM(F33:F35) -> 12 | G32: =ROUND(F32/$F$2,1) -> 1.5 | H32: =MIN(H33:H35) -> 46342 | I32: =MAX(I33:I35) -> 46343 | J32: Trần Phương Hạo | K32: Must | L32: Thêm/sửa/ẩn dòng giá; khoảng giá không chồng lấn; có ngày áp dụng
A33: 2.4.1 | B33: 3 | C33: Phân tích và thiết kế PB07 | D33: 2 | F33: =$B$3*E32*$D$3 -> 2.4 | G33: =ROUND(F33/$F$2,2) -> 0.3 | H33: =WORKDAY($H$19,INT(M33/$F$2)) -> 46342 | I33: =WORKDAY($H$19,INT((M33+F33)/$F$2-0.000001)) -> 46342 | J33: Trần Phương Hạo | M33: =SUMIFS($F$6:$F32,$D$6:$D32,$D33,$B$6:$B32,3) -> 44
A34: 2.4.2 | B34: 3 | C34: Lập trình PB07 | D34: 2 | F34: =$B$3*E32*$F$3 -> 7.2 | G34: =ROUND(F34/$F$2,2) -> 0.9 | H34: =WORKDAY($H$19,INT(M34/$F$2)) -> 46342 | I34: =WORKDAY($H$19,INT((M34+F34)/$F$2-0.000001)) -> 46343 | J34: Trần Phương Hạo | M34: =SUMIFS($F$6:$F33,$D$6:$D33,$D34,$B$6:$B33,3) -> 46.4
A35: 2.4.3 | B35: 3 | C35: Kiểm thử PB07 | D35: 2 | F35: =$B$3*E32*$H$3 -> 2.4 | G35: =ROUND(F35/$F$2,2) -> 0.3 | H35: =WORKDAY($H$19,INT(M35/$F$2)) -> 46343 | I35: =WORKDAY($H$19,INT((M35+F35)/$F$2-0.000001)) -> 46343 | J35: Trần Phương Hạo | M35: =SUMIFS($F$6:$F34,$D$6:$D34,$D35,$B$6:$B34,3) -> 53.6
A36: 2.5 | B36: 2 | C36: PB08 - Kiểm tra hàng hóa | D36: 2 | E36: 5 | F36: =SUM(F37:F39) -> 20 | G36: =ROUND(F36/$F$2,1) -> 2.5 | H36: =MIN(H37:H39) -> 46344 | I36: =MAX(I37:I39) -> 46346 | J36: Trần Phương Hạo | K36: Must | L36: Căn cứ chọn phương tiện và mức giá; validate số > 0; chỉ nhập cho đơn đã có yêu cầu lấy hàng
A37: 2.5.1 | B37: 3 | C37: Phân tích và thiết kế PB08 | D37: 2 | F37: =$B$3*E36*$D$3 -> 4 | G37: =ROUND(F37/$F$2,2) -> 0.5 | H37: =WORKDAY($H$19,INT(M37/$F$2)) -> 46344 | I37: =WORKDAY($H$19,INT((M37+F37)/$F$2-0.000001)) -> 46344 | J37: Trần Phương Hạo | M37: =SUMIFS($F$6:$F36,$D$6:$D36,$D37,$B$6:$B36,3) -> 56
A38: 2.5.2 | B38: 3 | C38: Lập trình PB08 | D38: 2 | F38: =$B$3*E36*$F$3 -> 12 | G38: =ROUND(F38/$F$2,2) -> 1.5 | H38: =WORKDAY($H$19,INT(M38/$F$2)) -> 46344 | I38: =WORKDAY($H$19,INT((M38+F38)/$F$2-0.000001)) -> 46345 | J38: Trần Phương Hạo | M38: =SUMIFS($F$6:$F37,$D$6:$D37,$D38,$B$6:$B37,3) -> 60
A39: 2.5.3 | B39: 3 | C39: Kiểm thử PB08 | D39: 2 | F39: =$B$3*E36*$H$3 -> 4 | G39: =ROUND(F39/$F$2,2) -> 0.5 | H39: =WORKDAY($H$19,INT(M39/$F$2)) -> 46346 | I39: =WORKDAY($H$19,INT((M39+F39)/$F$2-0.000001)) -> 46346 | J39: Trần Phương Hạo | M39: =SUMIFS($F$6:$F38,$D$6:$D38,$D39,$B$6:$B38,3) -> 72
A40: 3 | B40: 1 | C40: Sprint 3 | D40: 3 | E40: =SUMIFS(E41:E64,B41:B64,2) -> 20 | F40: =SUMIFS(F41:F64,B41:B64,2) -> 80 | G40: =ROUND(F40/$F$2,1) -> 10 | H40: =$B$2+$D$2*(D40-1) -> 46349 | I40: =H40+$D$2-1 -> 46362 | J40: Trần Phương Hạo
A41: 3.1 | B41: 2 | C41: PB09 - Đề xuất, chọn phương tiện giao hàng | D41: 3 | E41: 3 | F41: =SUM(F42:F44) -> 12 | G41: =ROUND(F41/$F$2,1) -> 1.5 | H41: =MIN(H42:H44) -> 46349 | I41: =MAX(I42:I44) -> 46350 | J41: Trần Phương Hạo | K41: Should | L41: Gợi ý theo trọng lượng, kích thước, khoảng cách; cho đổi thủ công; dùng danh mục PB15
...

Sheet Gantt
A1: GANTT CHART - HỆ THỐNG QUẢN LÝ GIAO HÀNG
A2: Thanh xanh đậm = Sprint, xanh vừa = Story (PB), xanh nhạt = task con. Cột xám = thứ Bảy/Chủ nhật. Nhấn nút +/- bên trái để thu gọn/mở rộng.
F4: =IF(OR(0=0,DAY(F5)=1),TEXT(F5,"mm/yy"),"") -> 10/26 | G4: =IF(OR(1=0,DAY(G5)=1),TEXT(G5,"mm/yy"),"") | H4: =IF(OR(2=0,DAY(H5)=1),TEXT(H5,"mm/yy"),"") | I4: =IF(OR(3=0,DAY(I5)=1),TEXT(I5,"mm/yy"),"") | J4: =IF(OR(4=0,DAY(J5)=1),TEXT(J5,"mm/yy"),"") | K4: =IF(OR(5=0,DAY(K5)=1),TEXT(K5,"mm/yy"),"") | L4: =IF(OR(6=0,DAY(L5)=1),TEXT(L5,"mm/yy"),"") -> 11/26 | M4: =IF(OR(7=0,DAY(M5)=1),TEXT(M5,"mm/yy"),"") | N4: =IF(OR(8=0,DAY(N5)=1),TEXT(N5,"mm/yy"),"") | O4: =IF(OR(9=0,DAY(O5)=1),TEXT(O5,"mm/yy"),"") | P4: =IF(OR(10=0,DAY(P5)=1),TEXT(P5,"mm/yy"),"") | Q4: =IF(OR(11=0,DAY(Q5)=1),TEXT(Q5,"mm/yy"),"") | R4: =IF(OR(12=0,DAY(R5)=1),TEXT(R5,"mm/yy"),"") | S4: =IF(OR(13=0,DAY(S5)=1),TEXT(S5,"mm/yy"),"") | T4: =IF(OR(14=0,DAY(T5)=1),TEXT(T5,"mm/yy"),"") | U4: =IF(OR(15=0,DAY(U5)=1),TEXT(U5,"mm/yy"),"") | V4: =IF(OR(16=0,DAY(V5)=1),TEXT(V5,"mm/yy"),"") | W4: =IF(OR(17=0,DAY(W5)=1),TEXT(W5,"mm/yy"),"") | X4: =IF(OR(18=0,DAY(X5)=1),TEXT(X5,"mm/yy"),"") | Y4: =IF(OR(19=0,DAY(Y5)=1),TEXT(Y5,"mm/yy"),"") | Z4: =IF(OR(20=0,DAY(Z5)=1),TEXT(Z5,"mm/yy"),"") | AA4: =IF(OR(21=0,DAY(AA5)=1),TEXT(AA5,"mm/yy"),"") | AB4: =IF(OR(22=0,DAY(AB5)=1),TEXT(AB5,"mm/yy"),"") | AC4: =IF(OR(23=0,DAY(AC5)=1),TEXT(AC5,"mm/yy"),"") | AD4: =IF(OR(24=0,DAY(AD5)=1),TEXT(AD5,"mm/yy"),"") | AE4: =IF(OR(25=0,DAY(AE5)=1),TEXT(AE5,"mm/yy"),"") | AF4: =IF(OR(26=0,DAY(AF5)=1),TEXT(AF5,"mm/yy"),"") | AG4: =IF(OR(27=0,DAY(AG5)=1),TEXT(AG5,"mm/yy"),"") | AH4: =IF(OR(28=0,DAY(AH5)=1),TEXT(AH5,"mm/yy"),"") | AI4: =IF(OR(29=0,DAY(AI5)=1),TEXT(AI5,"mm/yy"),"") | AJ4: =IF(OR(30=0,DAY(AJ5)=1),TEXT(AJ5,"mm/yy"),"") | AK4: =IF(OR(31=0,DAY(AK5)=1),TEXT(AK5,"mm/yy"),"") | AL4: =IF(OR(32=0,DAY(AL5)=1),TEXT(AL5,"mm/yy"),"") | AM4: =IF(OR(33=0,DAY(AM5)=1),TEXT(AM5,"mm/yy"),"") | AN4: =IF(OR(34=0,DAY(AN5)=1),TEXT(AN5,"mm/yy"),"") | AO4: =IF(OR(35=0,DAY(AO5)=1),TEXT(AO5,"mm/yy"),"") | AP4: =IF(OR(36=0,DAY(AP5)=1),TEXT(AP5,"mm/yy"),"") -> 12/26 | AQ4: =IF(OR(37=0,DAY(AQ5)=1),TEXT(AQ5,"mm/yy"),"") | AR4: =IF(OR(38=0,DAY(AR5)=1),TEXT(AR5,"mm/yy"),"") | AS4: =IF(OR(39=0,DAY(AS5)=1),TEXT(AS5,"mm/yy"),"") | AT4: =IF(OR(40=0,DAY(AT5)=1),TEXT(AT5,"mm/yy"),"") | AU4: =IF(OR(41=0,DAY(AU5)=1),TEXT(AU5,"mm/yy"),"") | AV4: =IF(OR(42=0,DAY(AV5)=1),TEXT(AV5,"mm/yy"),"") | AW4: =IF(OR(43=0,DAY(AW5)=1),TEXT(AW5,"mm/yy"),"") | AX4: =IF(OR(44=0,DAY(AX5)=1),TEXT(AX5,"mm/yy"),"") | AY4: =IF(OR(45=0,DAY(AY5)=1),TEXT(AY5,"mm/yy"),"") | AZ4: =IF(OR(46=0,DAY(AZ5)=1),TEXT(AZ5,"mm/yy"),"") | BA4: =IF(OR(47=0,DAY(BA5)=1),TEXT(BA5,"mm/yy"),"") | BB4: =IF(OR(48=0,DAY(BB5)=1),TEXT(BB5,"mm/yy"),"") | BC4: =IF(OR(49=0,DAY(BC5)=1),TEXT(BC5,"mm/yy"),"") | BD4: =IF(OR(50=0,DAY(BD5)=1),TEXT(BD5,"mm/yy"),"") | BE4: =IF(OR(51=0,DAY(BE5)=1),TEXT(BE5,"mm/yy"),"") | BF4: =IF(OR(52=0,DAY(BF5)=1),TEXT(BF5,"mm/yy"),"") | BG4: =IF(OR(53=0,DAY(BG5)=1),TEXT(BG5,"mm/yy"),"") | BH4: =IF(OR(54=0,DAY(BH5)=1),TEXT(BH5,"mm/yy"),"") | BI4: =IF(OR(55=0,DAY(BI5)=1),TEXT(BI5,"mm/yy"),"") | BJ4: =IF(OR(56=0,DAY(BJ5)=1),TEXT(BJ5,"mm/yy"),"") | BK4: =IF(OR(57=0,DAY(BK5)=1),TEXT(BK5,"mm/yy"),"") | BL4: =IF(OR(58=0,DAY(BL5)=1),TEXT(BL5,"mm/yy"),"") | BM4: =IF(OR(59=0,DAY(BM5)=1),TEXT(BM5,"mm/yy"),"") | BN4: =IF(OR(60=0,DAY(BN5)=1),TEXT(BN5,"mm/yy"),"") | BO4: =IF(OR(61=0,DAY(BO5)=1),TEXT(BO5,"mm/yy"),"") | BP4: =IF(OR(62=0,DAY(BP5)=1),TEXT(BP5,"mm/yy"),"") | BQ4: =IF(OR(63=0,DAY(BQ5)=1),TEXT(BQ5,"mm/yy"),"") | BR4: =IF(OR(64=0,DAY(BR5)=1),TEXT(BR5,"mm/yy"),"") | BS4: =IF(OR(65=0,DAY(BS5)=1),TEXT(BS5,"mm/yy"),"") | BT4: =IF(OR(66=0,DAY(BT5)=1),TEXT(BT5,"mm/yy"),"") | BU4: =IF(OR(67=0,DAY(BU5)=1),TEXT(BU5,"mm/yy"),"") -> 01/27 | BV4: =IF(OR(68=0,DAY(BV5)=1),TEXT(BV5,"mm/yy"),"") | BW4: =IF(OR(69=0,DAY(BW5)=1),TEXT(BW5,"mm/yy"),"") | BX4: =IF(OR(70=0,DAY(BX5)=1),TEXT(BX5,"mm/yy"),"") | BY4: =IF(OR(71=0,DAY(BY5)=1),TEXT(BY5,"mm/yy"),"") | BZ4: =IF(OR(72=0,DAY(BZ5)=1),TEXT(BZ5,"mm/yy"),"") | CA4: =IF(OR(73=0,DAY(CA5)=1),TEXT(CA5,"mm/yy"),"") | CB4: =IF(OR(74=0,DAY(CB5)=1),TEXT(CB5,"mm/yy"),"") | CC4: =IF(OR(75=0,DAY(CC5)=1),TEXT(CC5,"mm/yy"),"") | CD4: =IF(OR(76=0,DAY(CD5)=1),TEXT(CD5,"mm/yy"),"") | CE4: =IF(OR(77=0,DAY(CE5)=1),TEXT(CE5,"mm/yy"),"") | CF4: =IF(OR(78=0,DAY(CF5)=1),TEXT(CF5,"mm/yy"),"") | CG4: =IF(OR(79=0,DAY(CG5)=1),TEXT(CG5,"mm/yy"),"") | CH4: =IF(OR(80=0,DAY(CH5)=1),TEXT(CH5,"mm/yy"),"") | CI4: =IF(OR(81=0,DAY(CI5)=1),TEXT(CI5,"mm/yy"),"") | CJ4: =IF(OR(82=0,DAY(CJ5)=1),TEXT(CJ5,"mm/yy"),"") | CK4: =IF(OR(83=0,DAY(CK5)=1),TEXT(CK5,"mm/yy"),"")
A5: WBS | B5: Level | C5: Task Name | D5: Start | E5: Finish | F5: =WBS!$B$2+0 -> 46321 | G5: =WBS!$B$2+1 -> 46322 | H5: =WBS!$B$2+2 -> 46323 | I5: =WBS!$B$2+3 -> 46324 | J5: =WBS!$B$2+4 -> 46325 | K5: =WBS!$B$2+5 -> 46326 | L5: =WBS!$B$2+6 -> 46327 | M5: =WBS!$B$2+7 -> 46328 | N5: =WBS!$B$2+8 -> 46329 | O5: =WBS!$B$2+9 -> 46330 | P5: =WBS!$B$2+10 -> 46331 | Q5: =WBS!$B$2+11 -> 46332 | R5: =WBS!$B$2+12 -> 46333 | S5: =WBS!$B$2+13 -> 46334 | T5: =WBS!$B$2+14 -> 46335 | U5: =WBS!$B$2+15 -> 46336 | V5: =WBS!$B$2+16 -> 46337 | W5: =WBS!$B$2+17 -> 46338 | X5: =WBS!$B$2+18 -> 46339 | Y5: =WBS!$B$2+19 -> 46340 | Z5: =WBS!$B$2+20 -> 46341 | AA5: =WBS!$B$2+21 -> 46342 | AB5: =WBS!$B$2+22 -> 46343 | AC5: =WBS!$B$2+23 -> 46344 | AD5: =WBS!$B$2+24 -> 46345 | AE5: =WBS!$B$2+25 -> 46346 | AF5: =WBS!$B$2+26 -> 46347 | AG5: =WBS!$B$2+27 -> 46348 | AH5: =WBS!$B$2+28 -> 46349 | AI5: =WBS!$B$2+29 -> 46350 | AJ5: =WBS!$B$2+30 -> 46351 | AK5: =WBS!$B$2+31 -> 46352 | AL5: =WBS!$B$2+32 -> 46353 | AM5: =WBS!$B$2+33 -> 46354 | AN5: =WBS!$B$2+34 -> 46355 | AO5: =WBS!$B$2+35 -> 46356 | AP5: =WBS!$B$2+36 -> 46357 | AQ5: =WBS!$B$2+37 -> 46358 | AR5: =WBS!$B$2+38 -> 46359 | AS5: =WBS!$B$2+39 -> 46360 | AT5: =WBS!$B$2+40 -> 46361 | AU5: =WBS!$B$2+41 -> 46362 | AV5: =WBS!$B$2+42 -> 46363 | AW5: =WBS!$B$2+43 -> 46364 | AX5: =WBS!$B$2+44 -> 46365 | AY5: =WBS!$B$2+45 -> 46366 | AZ5: =WBS!$B$2+46 -> 46367 | BA5: =WBS!$B$2+47 -> 46368 | BB5: =WBS!$B$2+48 -> 46369 | BC5: =WBS!$B$2+49 -> 46370 | BD5: =WBS!$B$2+50 -> 46371 | BE5: =WBS!$B$2+51 -> 46372 | BF5: =WBS!$B$2+52 -> 46373 | BG5: =WBS!$B$2+53 -> 46374 | BH5: =WBS!$B$2+54 -> 46375 | BI5: =WBS!$B$2+55 -> 46376 | BJ5: =WBS!$B$2+56 -> 46377 | BK5: =WBS!$B$2+57 -> 46378 | BL5: =WBS!$B$2+58 -> 46379 | BM5: =WBS!$B$2+59 -> 46380 | BN5: =WBS!$B$2+60 -> 46381 | BO5: =WBS!$B$2+61 -> 46382 | BP5: =WBS!$B$2+62 -> 46383 | BQ5: =WBS!$B$2+63 -> 46384 | BR5: =WBS!$B$2+64 -> 46385 | BS5: =WBS!$B$2+65 -> 46386 | BT5: =WBS!$B$2+66 -> 46387 | BU5: =WBS!$B$2+67 -> 46388 | BV5: =WBS!$B$2+68 -> 46389 | BW5: =WBS!$B$2+69 -> 46390 | BX5: =WBS!$B$2+70 -> 46391 | BY5: =WBS!$B$2+71 -> 46392 | BZ5: =WBS!$B$2+72 -> 46393 | CA5: =WBS!$B$2+73 -> 46394 | CB5: =WBS!$B$2+74 -> 46395 | CC5: =WBS!$B$2+75 -> 46396 | CD5: =WBS!$B$2+76 -> 46397 | CE5: =WBS!$B$2+77 -> 46398 | CF5: =WBS!$B$2+78 -> 46399 | CG5: =WBS!$B$2+79 -> 46400 | CH5: =WBS!$B$2+80 -> 46401 | CI5: =WBS!$B$2+81 -> 46402 | CJ5: =WBS!$B$2+82 -> 46403 | CK5: =WBS!$B$2+83 -> 46404
A6: =WBS!A6 -> 1 | B6: =WBS!B6 -> 1 | C6: =WBS!C6 -> Sprint 1 | D6: =WBS!H6 -> 46321 | E6: =WBS!I6 -> 46334
A7: =WBS!A7 -> 1.1 | B7: =WBS!B7 -> 2 | C7: =WBS!C7 -> PB01 - Khởi tạo dự án .NET 8 + MySQL | D7: =WBS!H7 -> 46321 | E7: =WBS!I7 -> 46323
A8: =WBS!A8 -> 1.1.1 | B8: =WBS!B8 -> 3 | C8: =WBS!C8 -> Phân tích và thiết kế PB01 | D8: =WBS!H8 -> 46321 | E8: =WBS!I8 -> 46321
A9: =WBS!A9 -> 1.1.2 | B9: =WBS!B9 -> 3 | C9: =WBS!C9 -> Lập trình PB01 | D9: =WBS!H9 -> 46321 | E9: =WBS!I9 -> 46322
A10: =WBS!A10 -> 1.1.3 | B10: =WBS!B10 -> 3 | C10: =WBS!C10 -> Kiểm thử PB01 | D10: =WBS!H10 -> 46323 | E10: =WBS!I10 -> 46323
A11: =WBS!A11 -> 1.2 | B11: =WBS!B11 -> 2 | C11: =WBS!C11 -> PB02 - Đăng nhập và phân quyền theo vai trò | D11: =WBS!H11 -> 46323 | E11: =WBS!I11 -> 46325
A12: =WBS!A12 -> 1.2.1 | B12: =WBS!B12 -> 3 | C12: =WBS!C12 -> Phân tích và thiết kế PB02 | D12: =WBS!H12 -> 46323 | E12: =WBS!I12 -> 46323
A13: =WBS!A13 -> 1.2.2 | B13: =WBS!B13 -> 3 | C13: =WBS!C13 -> Lập trình PB02 | D13: =WBS!H13 -> 46324 | E13: =WBS!I13 -> 46325
A14: =WBS!A14 -> 1.2.3 | B14: =WBS!B14 -> 3 | C14: =WBS!C14 -> Kiểm thử PB02 | D14: =WBS!H14 -> 46325 | E14: =WBS!I14 -> 46325
A15: =WBS!A15 -> 1.3 | B15: =WBS!B15 -> 2 | C15: =WBS!C15 -> PB03 - Quản lý tài khoản nhân viên | D15: =WBS!H15 -> 46328 | E15: =WBS!I15 -> 46329
A16: =WBS!A16 -> 1.3.1 | B16: =WBS!B16 -> 3 | C16: =WBS!C16 -> Phân tích và thiết kế PB03 | D16: =WBS!H16 -> 46328 | E16: =WBS!I16 -> 46328
A17: =WBS!A17 -> 1.3.2 | B17: =WBS!B17 -> 3 | C17: =WBS!C17 -> Lập trình PB03 | D17: =WBS!H17 -> 46328 | E17: =WBS!I17 -> 46329
... A119: =WBS!A119 -> 6.5.3 | B119: =WBS!B119 -> 3 | C119: =WBS!C119 -> Kiểm thử PB27 | D119: =WBS!H119 -> 46401 | E119: =WBS!I119 -> 46401

Sheet Resources
A1: Resource Name | B1: Vai trò | C1: Max Units | D1: Giờ/ngày
A2: Trần Phương Hạo | B2: Scrum Master, Developer (Fullstack) | C2: 1 | D2: 8
A4: Nguồn: sheet Team trong Product Backlog.

Sheet Sprint 1
A1: BURNDOWN CHART - SPRINT 1
A2: Tổng điểm KH: | B2: =WBS!E6 -> 13 | C2: Bắt đầu: | D2: =WBS!H6 -> 46321 | E2: Số ngày: | F2: =WBS!$D$2 -> 14
A3: Giờ KH: | B3: =WBS!F6 -> 52 | C3: Năng lực (giờ): | D3: =NETWORKDAYS(D2,D2+F2-1)*WBS!$F$2 -> 80 | E3: Dư/thiếu: | F3: =D3-B3 -> 28
A5: Ngày | B5: Ngày lịch | C5: Lý tưởng | D5: Kế hoạch theo WBS | E5: Thực tế (điểm còn lại)
A6: 0 | B6: Bắt đầu | C6: =ROUND($B$2*(1-A6/$F$2),1) -> 13 | D6: =$B$2-SUMIFS($J$27:$J$29,$L$27:$L$29,"<="&A6) -> 13 | E6: =B2 -> 13
A7: 1 | B7: =$D$2+A7-1 -> 46321 | C7: =ROUND($B$2*(1-A7/$F$2),1) -> 12.1 | D7: =$B$2-SUMIFS($J$27:$J$29,$L$27:$L$29,"<="&A7) -> 13
A8: 2 | B8: =$D$2+A8-1 -> 46322 | C8: =ROUND($B$2*(1-A8/$F$2),1) -> 11.1 | D8: =$B$2-SUMIFS($J$27:$J$29,$L$27:$L$29,"<="&A8) -> 13
A9: 3 | B9: =$D$2+A9-1 -> 46323 | C9: =ROUND($B$2*(1-A9/$F$2),1) -> 10.2 | D9: =$B$2-SUMIFS($J$27:$J$29,$L$27:$L$29,"<="&A9) -> 8
A10: 4 | B10: =$D$2+A10-1 -> 46324 | C10: =ROUND($B$2*(1-A10/$F$2),1) -> 9.3 | D10: =$B$2-SUMIFS($J$27:$J$29,$L$27:$L$29,"<="&A10) -> 8
A11: 5 | B11: =$D$2+A11-1 -> 46325 | C11: =ROUND($B$2*(1-A11/$F$2),1) -> 8.4 | D11: =$B$2-SUMIFS($J$27:$J$29,$L$27:$L$29,"<="&A11) -> 3
A12: 6 | B12: =$D$2+A12-1 -> 46326 | C12: =ROUND($B$2*(1-A12/$F$2),1) -> 7.4 | D12: =$B$2-SUMIFS($J$27:$J$29,$L$27:$L$29,"<="&A12) -> 3
A13: 7 | B13: =$D$2+A13-1 -> 46327 | C13: =ROUND($B$2*(1-A13/$F$2),1) -> 6.5 | D13: =$B$2-SUMIFS($J$27:$J$29,$L$27:$L$29,"<="&A13) -> 3
A14: 8 | B14: =$D$2+A14-1 -> 46328 | C14: =ROUND($B$2*(1-A14/$F$2),1) -> 5.6 | D14: =$B$2-SUMIFS($J$27:$J$29,$L$27:$L$29,"<="&A14) -> 3
A15: 9 | B15: =$D$2+A15-1 -> 46329 | C15: =ROUND($B$2*(1-A15/$F$2),1) -> 4.6 | D15: =$B$2-SUMIFS($J$27:$J$29,$L$27:$L$29,"<="&A15) -> 0
A16: 10 | B16: =$D$2+A16-1 -> 46330 | C16: =ROUND($B$2*(1-A16/$F$2),1) -> 3.7 | D16: =$B$2-SUMIFS($J$27:$J$29,$L$27:$L$29,"<="&A16) -> 0
A17: 11 | B17: =$D$2+A17-1 -> 46331 | C17: =ROUND($B$2*(1-A17/$F$2),1) -> 2.8 | D17: =$B$2-SUMIFS($J$27:$J$29,$L$27:$L$29,"<="&A17) -> 0
A18: 12 | B18: =$D$2+A18-1 -> 46332 | C18: =ROUND($B$2*(1-A18/$F$2),1) -> 1.9 | D18: =$B$2-SUMIFS($J$27:$J$29,$L$27:$L$29,"<="&A18) -> 0
... A20: 14 | B20: =$D$2+A20-1 -> 46334 | C20: =ROUND($B$2*(1-A20/$F$2),1) -> 0 | D20: =$B$2-SUMIFS($J$27:$J$29,$L$27:$L$29,"<="&A20) -> 0
A22: Thực tế: cuối mỗi ngày điền số điểm CÒN LẠI của sprint vào cột E (ô vàng); ô trống không vẽ lên biểu đồ.
A23: Kế hoạch theo WBS: điểm của story trừ dần vào ngày story đó kết thúc theo lịch ở sheet WBS.
H26: Story | I26: Tên story | J26: Điểm | K26: Kết thúc KH | L26: Ngày thứ (KH)
H27: =LEFT(WBS!C7,4) -> PB01 | I27: =MID(WBS!C7,8,200) -> Khởi tạo dự án .NET 8 + MySQL | J27: =WBS!E7 -> 5 | K27: =WBS!I7 -> 46323 | L27: =K27-$D$2+1 -> 3
H28: =LEFT(WBS!C11,4) -> PB02 | I28: =MID(WBS!C11,8,200) -> Đăng nhập và phân quyền theo vai trò | J28: =WBS!E11 -> 5 | K28: =WBS!I11 -> 46325 | L28: =K28-$D$2+1 -> 5
H29: =LEFT(WBS!C15,4) -> PB03 | I29: =MID(WBS!C15,8,200) -> Quản lý tài khoản nhân viên | J29: =WBS!E15 -> 3 | K29: =WBS!I15 -> 46329 | L29: =K29-$D$2+1 -> 9

Sheet Sprint 2
A1: BURNDOWN CHART - SPRINT 2
A2: Tổng điểm KH: | B2: =WBS!E19 -> 19 | C2: Bắt đầu: | D2: =WBS!H19 -> 46335 | E2: Số ngày: | F2: =WBS!$D$2 -> 14
A3: Giờ KH: | B3: =WBS!F19 -> 76 | C3: Năng lực (giờ): | D3: =NETWORKDAYS(D2,D2+F2-1)*WBS!$F$2 -> 80 | E3: Dư/thiếu: | F3: =D3-B3 -> 4
A5: Ngày | B5: Ngày lịch | C5: Lý tưởng | D5: Kế hoạch theo WBS | E5: Thực tế (điểm còn lại)
A6: 0 | B6: Bắt đầu | C6: =ROUND($B$2*(1-A6/$F$2),1) -> 19 | D6: =$B$2-SUMIFS($J$27:$J$31,$L$27:$L$31,"<="&A6) -> 19 | E6: =B2 -> 19
A7: 1 | B7: =$D$2+A7-1 -> 46335 | C7: =ROUND($B$2*(1-A7/$F$2),1) -> 17.6 | D7: =$B$2-SUMIFS($J$27:$J$31,$L$27:$L$31,"<="&A7) -> 19
A8: 2 | B8: =$D$2+A8-1 -> 46336 | C8: =ROUND($B$2*(1-A8/$F$2),1) -> 16.3 | D8: =$B$2-SUMIFS($J$27:$J$31,$L$27:$L$31,"<="&A8) -> 19
A9: 3 | B9: =$D$2+A9-1 -> 46337 | C9: =ROUND($B$2*(1-A9/$F$2),1) -> 14.9 | D9: =$B$2-SUMIFS($J$27:$J$31,$L$27:$L$31,"<="&A9) -> 14
A10: 4 | B10: =$D$2+A10-1 -> 46338 | C10: =ROUND($B$2*(1-A10/$F$2),1) -> 13.6 | D10: =$B$2-SUMIFS($J$27:$J$31,$L$27:$L$31,"<="&A10) -> 11
A11: 5 | B11: =$D$2+A11-1 -> 46339 | C11: =ROUND($B$2*(1-A11/$F$2),1) -> 12.2 | D11: =$B$2-SUMIFS($J$27:$J$31,$L$27:$L$31,"<="&A11) -> 11
A12: 6 | B12: =$D$2+A12-1 -> 46340 | C12: =ROUND($B$2*(1-A12/$F$2),1) -> 10.9 | D12: =$B$2-SUMIFS($J$27:$J$31,$L$27:$L$31,"<="&A12) -> 11
A13: 7 | B13: =$D$2+A13-1 -> 46341 | C13: =ROUND($B$2*(1-A13/$F$2),1) -> 9.5 | D13: =$B$2-SUMIFS($J$27:$J$31,$L$27:$L$31,"<="&A13) -> 11
A14: 8 | B14: =$D$2+A14-1 -> 46342 | C14: =ROUND($B$2*(1-A14/$F$2),1) -> 8.1 | D14: =$B$2-SUMIFS($J$27:$J$31,$L$27:$L$31,"<="&A14) -> 8
A15: 9 | B15: =$D$2+A15-1 -> 46343 | C15: =ROUND($B$2*(1-A15/$F$2),1) -> 6.8 | D15: =$B$2-SUMIFS($J$27:$J$31,$L$27:$L$31,"<="&A15) -> 5
A16: 10 | B16: =$D$2+A16-1 -> 46344 | C16: =ROUND($B$2*(1-A16/$F$2),1) -> 5.4 | D16: =$B$2-SUMIFS($J$27:$J$31,$L$27:$L$31,"<="&A16) -> 5
A17: 11 | B17: =$D$2+A17-1 -> 46345 | C17: =ROUND($B$2*(1-A17/$F$2),1) -> 4.1 | D17: =$B$2-SUMIFS($J$27:$J$31,$L$27:$L$31,"<="&A17) -> 5
A18: 12 | B18: =$D$2+A18-1 -> 46346 | C18: =ROUND($B$2*(1-A18/$F$2),1) -> 2.7 | D18: =$B$2-SUMIFS($J$27:$J$31,$L$27:$L$31,"<="&A18) -> 0
... A20: 14 | B20: =$D$2+A20-1 -> 46348 | C20: =ROUND($B$2*(1-A20/$F$2),1) -> 0 | D20: =$B$2-SUMIFS($J$27:$J$31,$L$27:$L$31,"<="&A20) -> 0
A22: Thực tế: cuối mỗi ngày điền số điểm CÒN LẠI của sprint vào cột E (ô vàng); ô trống không vẽ lên biểu đồ.
A23: Kế hoạch theo WBS: điểm của story trừ dần vào ngày story đó kết thúc theo lịch ở sheet WBS.
H26: Story | I26: Tên story | J26: Điểm | K26: Kết thúc KH | L26: Ngày thứ (KH)
H27: =LEFT(WBS!C20,4) -> PB04 | I27: =MID(WBS!C20,8,200) -> Nhận mã đơn hàng từ website bán hàng (API) | J27: =WBS!E20 -> 5 | K27: =WBS!I20 -> 46337 | L27: =K27-$D$2+1 -> 3
H28: =LEFT(WBS!C24,4) -> PB05 | I28: =MID(WBS!C24,8,200) -> Gửi yêu cầu giao hàng đến nhận hàng từ công ty | J28: =WBS!E24 -> 3 | K28: =WBS!I24 -> 46338 | L28: =K28-$D$2+1 -> 4
H29: =LEFT(WBS!C28,4) -> PB06 | I29: =MID(WBS!C28,8,200) -> Cập nhật trạng thái đơn hàng tuần tự | J29: =WBS!E28 -> 3 | K29: =WBS!I28 -> 46342 | L29: =K29-$D$2+1 -> 8
H30: =LEFT(WBS!C32,4) -> PB07 | I30: =MID(WBS!C32,8,200) -> Quản lý bảng báo giá | J30: =WBS!E32 -> 3 | K30: =WBS!I32 -> 46343 | L30: =K30-$D$2+1 -> 9
H31: =LEFT(WBS!C36,4) -> PB08 | I31: =MID(WBS!C36,8,200) -> Kiểm tra hàng hóa | J31: =WBS!E36 -> 5 | K31: =WBS!I36 -> 46346 | L31: =K31-$D$2+1 -> 12

Sheet Sprint 3
A1: BURNDOWN CHART - SPRINT 3
A2: Tổng điểm KH: | B2: =WBS!E40 -> 20 | C2: Bắt đầu: | D2: =WBS!H40 -> 46349 | E2: Số ngày: | F2: =WBS!$D$2 -> 14
A3: Giờ KH: | B3: =WBS!F40 -> 80 | C3: Năng lực (giờ): | D3: =NETWORKDAYS(D2,D2+F2-1)*WBS!$F$2 -> 80 | E3: Dư/thiếu: | F3: =D3-B3 -> 0
A5: Ngày | B5: Ngày lịch | C5: Lý tưởng | D5: Kế hoạch theo WBS | E5: Thực tế (điểm còn lại)
A6: 0 | B6: Bắt đầu | C6: =ROUND($B$2*(1-A6/$F$2),1) -> 20 | D6: =$B$2-SUMIFS($J$27:$J$32,$L$27:$L$32,"<="&A6) -> 20 | E6: =B2 -> 20
A7: 1 | B7: =$D$2+A7-1 -> 46349 | C7: =ROUND($B$2*(1-A7/$F$2),1) -> 18.6 | D7: =$B$2-SUMIFS($J$27:$J$32,$L$27:$L$32,"<="&A7) -> 20
A8: 2 | B8: =$D$2+A8-1 -> 46350 | C8: =ROUND($B$2*(1-A8/$F$2),1) -> 17.1 | D8: =$B$2-SUMIFS($J$27:$J$32,$L$27:$L$32,"<="&A8) -> 17
A9: 3 | B9: =$D$2+A9-1 -> 46351 | C9: =ROUND($B$2*(1-A9/$F$2),1) -> 15.7 | D9: =$B$2-SUMIFS($J$27:$J$32,$L$27:$L$32,"<="&A9) -> 14
A10: 4 | B10: =$D$2+A10-1 -> 46352 | C10: =ROUND($B$2*(1-A10/$F$2),1) -> 14.3 | D10: =$B$2-SUMIFS($J$27:$J$32,$L$27:$L$32,"<="&A10) -> 14
A11: 5 | B11: =$D$2+A11-1 -> 46353 | C11: =ROUND($B$2*(1-A11/$F$2),1) -> 12.9 | D11: =$B$2-SUMIFS($J$27:$J$32,$L$27:$L$32,"<="&A11) -> 11
A12: 6 | B12: =$D$2+A12-1 -> 46354 | C12: =ROUND($B$2*(1-A12/$F$2),1) -> 11.4 | D12: =$B$2-SUMIFS($J$27:$J$32,$L$27:$L$32,"<="&A12) -> 11
A13: 7 | B13: =$D$2+A13-1 -> 46355 | C13: =ROUND($B$2*(1-A13/$F$2),1) -> 10 | D13: =$B$2-SUMIFS($J$27:$J$32,$L$27:$L$32,"<="&A13) -> 11
A14: 8 | B14: =$D$2+A14-1 -> 46356 | C14: =ROUND($B$2*(1-A14/$F$2),1) -> 8.6 | D14: =$B$2-SUMIFS($J$27:$J$32,$L$27:$L$32,"<="&A14) -> 8
A15: 9 | B15: =$D$2+A15-1 -> 46357 | C15: =ROUND($B$2*(1-A15/$F$2),1) -> 7.1 | D15: =$B$2-SUMIFS($J$27:$J$32,$L$27:$L$32,"<="&A15) -> 8
A16: 10 | B16: =$D$2+A16-1 -> 46358 | C16: =ROUND($B$2*(1-A16/$F$2),1) -> 5.7 | D16: =$B$2-SUMIFS($J$27:$J$32,$L$27:$L$32,"<="&A16) -> 5
A17: 11 | B17: =$D$2+A17-1 -> 46359 | C17: =ROUND($B$2*(1-A17/$F$2),1) -> 4.3 | D17: =$B$2-SUMIFS($J$27:$J$32,$L$27:$L$32,"<="&A17) -> 5
A18: 12 | B18: =$D$2+A18-1 -> 46360 | C18: =ROUND($B$2*(1-A18/$F$2),1) -> 2.9 | D18: =$B$2-SUMIFS($J$27:$J$32,$L$27:$L$32,"<="&A18) -> 0
... A20: 14 | B20: =$D$2+A20-1 -> 46362 | C20: =ROUND($B$2*(1-A20/$F$2),1) -> 0 | D20: =$B$2-SUMIFS($J$27:$J$32,$L$27:$L$32,"<="&A20) -> 0
A22: Thực tế: cuối mỗi ngày điền số điểm CÒN LẠI của sprint vào cột E (ô vàng); ô trống không vẽ lên biểu đồ.
A23: Kế hoạch theo WBS: điểm của story trừ dần vào ngày story đó kết thúc theo lịch ở sheet WBS.
H26: Story | I26: Tên story | J26: Điểm | K26: Kết thúc KH | L26: Ngày thứ (KH)
H27: =LEFT(WBS!C41,4) -> PB09 | I27: =MID(WBS!C41,8,200) -> Đề xuất, chọn phương tiện giao hàng | J27: =WBS!E41 -> 3 | K27: =WBS!I41 -> 46350 | L27: =K27-$D$2+1 -> 2
H28: =LEFT(WBS!C45,4) -> PB10 | I28: =MID(WBS!C45,8,200) -> Đưa ra mức giá theo bảng báo giá | J28: =WBS!E45 -> 3 | K28: =WBS!I45 -> 46351 | L28: =K28-$D$2+1 -> 3
H29: =LEFT(WBS!C49,4) -> PB11 | I29: =MID(WBS!C49,8,200) -> Nhập thông tin gói hàng | J29: =WBS!E49 -> 3 | K29: =WBS!I49 -> 46353 | L29: =K29-$D$2+1 -> 5
H30: =LEFT(WBS!C53,4) -> PB12 | I30: =MID(WBS!C53,8,200) -> Khai báo thông số kèm theo | J30: =WBS!E53 -> 3 | K30: =WBS!I53 -> 46356 | L30: =K30-$D$2+1 -> 8
H31: =LEFT(WBS!C57,4) -> PB15 | I31: =MID(WBS!C57,8,200) -> Quản lý danh mục loại hàng, tuyến xe, phương tiện | J31: =WBS!E57 -> 3 | K31: =WBS!I57 -> 46358 | L31: =K31-$D$2+1 -> 10
H32: =LEFT(WBS!C61,4) -> PB16 | I32: =MID(WBS!C61,8,200) -> Phân loại hàng hóa theo kích cỡ và tuyến xe | J32: =WBS!E61 -> 5 | K32: =WBS!I61 -> 46360 | L32: =K32-$D$2+1 -> 12

Sheet Sprint 4
A1: BURNDOWN CHART - SPRINT 4
A2: Tổng điểm KH: | B2: =WBS!E65 -> 19 | C2: Bắt đầu: | D2: =WBS!H65 -> 46363 | E2: Số ngày: | F2: =WBS!$D$2 -> 14
A3: Giờ KH: | B3: =WBS!F65 -> 76 | C3: Năng lực (giờ): | D3: =NETWORKDAYS(D2,D2+F2-1)*WBS!$F$2 -> 80 | E3: Dư/thiếu: | F3: =D3-B3 -> 4
A5: Ngày | B5: Ngày lịch | C5: Lý tưởng | D5: Kế hoạch theo WBS | E5: Thực tế (điểm còn lại)
A6: 0 | B6: Bắt đầu | C6: =ROUND($B$2*(1-A6/$F$2),1) -> 19 | D6: =$B$2-SUMIFS($J$27:$J$31,$L$27:$L$31,"<="&A6) -> 19 | E6: =B2 -> 19
A7: 1 | B7: =$D$2+A7-1 -> 46363 | C7: =ROUND($B$2*(1-A7/$F$2),1) -> 17.6 | D7: =$B$2-SUMIFS($J$27:$J$31,$L$27:$L$31,"<="&A7) -> 19
A8: 2 | B8: =$D$2+A8-1 -> 46364 | C8: =ROUND($B$2*(1-A8/$F$2),1) -> 16.3 | D8: =$B$2-SUMIFS($J$27:$J$31,$L$27:$L$31,"<="&A8) -> 16
A9: 3 | B9: =$D$2+A9-1 -> 46365 | C9: =ROUND($B$2*(1-A9/$F$2),1) -> 14.9 | D9: =$B$2-SUMIFS($J$27:$J$31,$L$27:$L$31,"<="&A9) -> 16
A10: 4 | B10: =$D$2+A10-1 -> 46366 | C10: =ROUND($B$2*(1-A10/$F$2),1) -> 13.6 | D10: =$B$2-SUMIFS($J$27:$J$31,$L$27:$L$31,"<="&A10) -> 11
A11: 5 | B11: =$D$2+A11-1 -> 46367 | C11: =ROUND($B$2*(1-A11/$F$2),1) -> 12.2 | D11: =$B$2-SUMIFS($J$27:$J$31,$L$27:$L$31,"<="&A11) -> 11
A12: 6 | B12: =$D$2+A12-1 -> 46368 | C12: =ROUND($B$2*(1-A12/$F$2),1) -> 10.9 | D12: =$B$2-SUMIFS($J$27:$J$31,$L$27:$L$31,"<="&A12) -> 11
A13: 7 | B13: =$D$2+A13-1 -> 46369 | C13: =ROUND($B$2*(1-A13/$F$2),1) -> 9.5 | D13: =$B$2-SUMIFS($J$27:$J$31,$L$27:$L$31,"<="&A13) -> 11
A14: 8 | B14: =$D$2+A14-1 -> 46370 | C14: =ROUND($B$2*(1-A14/$F$2),1) -> 8.1 | D14: =$B$2-SUMIFS($J$27:$J$31,$L$27:$L$31,"<="&A14) -> 8
A15: 9 | B15: =$D$2+A15-1 -> 46371 | C15: =ROUND($B$2*(1-A15/$F$2),1) -> 6.8 | D15: =$B$2-SUMIFS($J$27:$J$31,$L$27:$L$31,"<="&A15) -> 8
A16: 10 | B16: =$D$2+A16-1 -> 46372 | C16: =ROUND($B$2*(1-A16/$F$2),1) -> 5.4 | D16: =$B$2-SUMIFS($J$27:$J$31,$L$27:$L$31,"<="&A16) -> 3
A17: 11 | B17: =$D$2+A17-1 -> 46373 | C17: =ROUND($B$2*(1-A17/$F$2),1) -> 4.1 | D17: =$B$2-SUMIFS($J$27:$J$31,$L$27:$L$31,"<="&A17) -> 3
A18: 12 | B18: =$D$2+A18-1 -> 46374 | C18: =ROUND($B$2*(1-A18/$F$2),1) -> 2.7 | D18: =$B$2-SUMIFS($J$27:$J$31,$L$27:$L$31,"<="&A18) -> 0
... A20: 14 | B20: =$D$2+A20-1 -> 46376 | C20: =ROUND($B$2*(1-A20/$F$2),1) -> 0 | D20: =$B$2-SUMIFS($J$27:$J$31,$L$27:$L$31,"<="&A20) -> 0
A22: Thực tế: cuối mỗi ngày điền số điểm CÒN LẠI của sprint vào cột E (ô vàng); ô trống không vẽ lên biểu đồ.
A23: Kế hoạch theo WBS: điểm của story trừ dần vào ngày story đó kết thúc theo lịch ở sheet WBS.
H26: Story | I26: Tên story | J26: Điểm | K26: Kết thúc KH | L26: Ngày thứ (KH)
H27: =LEFT(WBS!C66,4) -> PB13 | I27: =MID(WBS!C66,8,200) -> Nhận tiền gửi thường (thu khi giao hàng) | J27: =WBS!E66 -> 3 | K27: =WBS!I66 -> 46364 | L27: =K27-$D$2+1 -> 2
H28: =LEFT(WBS!C70,4) -> PB14 | I28: =MID(WBS!C70,8,200) -> Nhận tiền gửi nhanh (chuyển khoản/trực tuyến) | J28: =WBS!E70 -> 5 | K28: =WBS!I70 -> 46366 | L28: =K28-$D$2+1 -> 4
H29: =LEFT(WBS!C74,4) -> PB17 | I29: =MID(WBS!C74,8,200) -> Phân công nhân viên giao hàng | J29: =WBS!E74 -> 3 | K29: =WBS!I74 -> 46370 | L29: =K29-$D$2+1 -> 8
H30: =LEFT(WBS!C78,4) -> PB18 | I30: =MID(WBS!C78,8,200) -> Giao hàng thường | J30: =WBS!E78 -> 5 | K30: =WBS!I78 -> 46372 | L30: =K30-$D$2+1 -> 10
H31: =LEFT(WBS!C82,4) -> PB23 | I31: =MID(WBS!C82,8,200) -> Lập phiếu giao hàng | J31: =WBS!E82 -> 3 | K31: =WBS!I82 -> 46374 | L31: =K31-$D$2+1 -> 12

Sheet Sprint 5
A1: BURNDOWN CHART - SPRINT 5
A2: Tổng điểm KH: | B2: =WBS!E86 -> 18 | C2: Bắt đầu: | D2: =WBS!H86 -> 46377 | E2: Số ngày: | F2: =WBS!$D$2 -> 14
A3: Giờ KH: | B3: =WBS!F86 -> 72 | C3: Năng lực (giờ): | D3: =NETWORKDAYS(D2,D2+F2-1)*WBS!$F$2 -> 80 | E3: Dư/thiếu: | F3: =D3-B3 -> 8
A5: Ngày | B5: Ngày lịch | C5: Lý tưởng | D5: Kế hoạch theo WBS | E5: Thực tế (điểm còn lại)
A6: 0 | B6: Bắt đầu | C6: =ROUND($B$2*(1-A6/$F$2),1) -> 18 | D6: =$B$2-SUMIFS($J$27:$J$29,$L$27:$L$29,"<="&A6) -> 18 | E6: =B2 -> 18
A7: 1 | B7: =$D$2+A7-1 -> 46377 | C7: =ROUND($B$2*(1-A7/$F$2),1) -> 16.7 | D7: =$B$2-SUMIFS($J$27:$J$29,$L$27:$L$29,"<="&A7) -> 18
A8: 2 | B8: =$D$2+A8-1 -> 46378 | C8: =ROUND($B$2*(1-A8/$F$2),1) -> 15.4 | D8: =$B$2-SUMIFS($J$27:$J$29,$L$27:$L$29,"<="&A8) -> 18
A9: 3 | B9: =$D$2+A9-1 -> 46379 | C9: =ROUND($B$2*(1-A9/$F$2),1) -> 14.1 | D9: =$B$2-SUMIFS($J$27:$J$29,$L$27:$L$29,"<="&A9) -> 13
A10: 4 | B10: =$D$2+A10-1 -> 46380 | C10: =ROUND($B$2*(1-A10/$F$2),1) -> 12.9 | D10: =$B$2-SUMIFS($J$27:$J$29,$L$27:$L$29,"<="&A10) -> 13
A11: 5 | B11: =$D$2+A11-1 -> 46381 | C11: =ROUND($B$2*(1-A11/$F$2),1) -> 11.6 | D11: =$B$2-SUMIFS($J$27:$J$29,$L$27:$L$29,"<="&A11) -> 8
A12: 6 | B12: =$D$2+A12-1 -> 46382 | C12: =ROUND($B$2*(1-A12/$F$2),1) -> 10.3 | D12: =$B$2-SUMIFS($J$27:$J$29,$L$27:$L$29,"<="&A12) -> 8
A13: 7 | B13: =$D$2+A13-1 -> 46383 | C13: =ROUND($B$2*(1-A13/$F$2),1) -> 9 | D13: =$B$2-SUMIFS($J$27:$J$29,$L$27:$L$29,"<="&A13) -> 8
A14: 8 | B14: =$D$2+A14-1 -> 46384 | C14: =ROUND($B$2*(1-A14/$F$2),1) -> 7.7 | D14: =$B$2-SUMIFS($J$27:$J$29,$L$27:$L$29,"<="&A14) -> 8
A15: 9 | B15: =$D$2+A15-1 -> 46385 | C15: =ROUND($B$2*(1-A15/$F$2),1) -> 6.4 | D15: =$B$2-SUMIFS($J$27:$J$29,$L$27:$L$29,"<="&A15) -> 8
A16: 10 | B16: =$D$2+A16-1 -> 46386 | C16: =ROUND($B$2*(1-A16/$F$2),1) -> 5.1 | D16: =$B$2-SUMIFS($J$27:$J$29,$L$27:$L$29,"<="&A16) -> 8
A17: 11 | B17: =$D$2+A17-1 -> 46387 | C17: =ROUND($B$2*(1-A17/$F$2),1) -> 3.9 | D17: =$B$2-SUMIFS($J$27:$J$29,$L$27:$L$29,"<="&A17) -> 0
A18: 12 | B18: =$D$2+A18-1 -> 46388 | C18: =ROUND($B$2*(1-A18/$F$2),1) -> 2.6 | D18: =$B$2-SUMIFS($J$27:$J$29,$L$27:$L$29,"<="&A18) -> 0
... A20: 14 | B20: =$D$2+A20-1 -> 46390 | C20: =ROUND($B$2*(1-A20/$F$2),1) -> 0 | D20: =$B$2-SUMIFS($J$27:$J$29,$L$27:$L$29,"<="&A20) -> 0
A22: Thực tế: cuối mỗi ngày điền số điểm CÒN LẠI của sprint vào cột E (ô vàng); ô trống không vẽ lên biểu đồ.
A23: Kế hoạch theo WBS: điểm của story trừ dần vào ngày story đó kết thúc theo lịch ở sheet WBS.
H26: Story | I26: Tên story | J26: Điểm | K26: Kết thúc KH | L26: Ngày thứ (KH)
H27: =LEFT(WBS!C87,4) -> PB19 | I27: =MID(WBS!C87,8,200) -> Giao hàng nhanh | J27: =WBS!E87 -> 5 | K27: =WBS!I87 -> 46379 | L27: =K27-$D$2+1 -> 3
H28: =LEFT(WBS!C91,4) -> PB20 | I28: =MID(WBS!C91,8,200) -> Cài đặt điểm check-in trên bản đồ | J28: =WBS!E91 -> 5 | K28: =WBS!I91 -> 46381 | L28: =K28-$D$2+1 -> 5
H29: =LEFT(WBS!C95,4) -> PB21 | I29: =MID(WBS!C95,8,200) -> Tự động check-in khi qua điểm đã cài đặt | J29: =WBS!E95 -> 8 | K29: =WBS!I95 -> 46387 | L29: =K29-$D$2+1 -> 11

Sheet Sprint 6
A1: BURNDOWN CHART - SPRINT 6
A2: Tổng điểm KH: | B2: =WBS!E99 -> 17 | C2: Bắt đầu: | D2: =WBS!H99 -> 46391 | E2: Số ngày: | F2: =WBS!$D$2 -> 14
A3: Giờ KH: | B3: =WBS!F99 -> 68 | C3: Năng lực (giờ): | D3: =NETWORKDAYS(D2,D2+F2-1)*WBS!$F$2 -> 80 | E3: Dư/thiếu: | F3: =D3-B3 -> 12
A5: Ngày | B5: Ngày lịch | C5: Lý tưởng | D5: Kế hoạch theo WBS | E5: Thực tế (điểm còn lại)
A6: 0 | B6: Bắt đầu | C6: =ROUND($B$2*(1-A6/$F$2),1) -> 17 | D6: =$B$2-SUMIFS($J$27:$J$31,$L$27:$L$31,"<="&A6) -> 17 | E6: =B2 -> 17
A7: 1 | B7: =$D$2+A7-1 -> 46391 | C7: =ROUND($B$2*(1-A7/$F$2),1) -> 15.8 | D7: =$B$2-SUMIFS($J$27:$J$31,$L$27:$L$31,"<="&A7) -> 17
A8: 2 | B8: =$D$2+A8-1 -> 46392 | C8: =ROUND($B$2*(1-A8/$F$2),1) -> 14.6 | D8: =$B$2-SUMIFS($J$27:$J$31,$L$27:$L$31,"<="&A8) -> 17
A9: 3 | B9: =$D$2+A9-1 -> 46393 | C9: =ROUND($B$2*(1-A9/$F$2),1) -> 13.4 | D9: =$B$2-SUMIFS($J$27:$J$31,$L$27:$L$31,"<="&A9) -> 12
A10: 4 | B10: =$D$2+A10-1 -> 46394 | C10: =ROUND($B$2*(1-A10/$F$2),1) -> 12.1 | D10: =$B$2-SUMIFS($J$27:$J$31,$L$27:$L$31,"<="&A10) -> 9
A11: 5 | B11: =$D$2+A11-1 -> 46395 | C11: =ROUND($B$2*(1-A11/$F$2),1) -> 10.9 | D11: =$B$2-SUMIFS($J$27:$J$31,$L$27:$L$31,"<="&A11) -> 9
A12: 6 | B12: =$D$2+A12-1 -> 46396 | C12: =ROUND($B$2*(1-A12/$F$2),1) -> 9.7 | D12: =$B$2-SUMIFS($J$27:$J$31,$L$27:$L$31,"<="&A12) -> 9
A13: 7 | B13: =$D$2+A13-1 -> 46397 | C13: =ROUND($B$2*(1-A13/$F$2),1) -> 8.5 | D13: =$B$2-SUMIFS($J$27:$J$31,$L$27:$L$31,"<="&A13) -> 9
A14: 8 | B14: =$D$2+A14-1 -> 46398 | C14: =ROUND($B$2*(1-A14/$F$2),1) -> 7.3 | D14: =$B$2-SUMIFS($J$27:$J$31,$L$27:$L$31,"<="&A14) -> 6
A15: 9 | B15: =$D$2+A15-1 -> 46399 | C15: =ROUND($B$2*(1-A15/$F$2),1) -> 6.1 | D15: =$B$2-SUMIFS($J$27:$J$31,$L$27:$L$31,"<="&A15) -> 3
A16: 10 | B16: =$D$2+A16-1 -> 46400 | C16: =ROUND($B$2*(1-A16/$F$2),1) -> 4.9 | D16: =$B$2-SUMIFS($J$27:$J$31,$L$27:$L$31,"<="&A16) -> 3
A17: 11 | B17: =$D$2+A17-1 -> 46401 | C17: =ROUND($B$2*(1-A17/$F$2),1) -> 3.6 | D17: =$B$2-SUMIFS($J$27:$J$31,$L$27:$L$31,"<="&A17) -> 0
A18: 12 | B18: =$D$2+A18-1 -> 46402 | C18: =ROUND($B$2*(1-A18/$F$2),1) -> 2.4 | D18: =$B$2-SUMIFS($J$27:$J$31,$L$27:$L$31,"<="&A18) -> 0
... A20: 14 | B20: =$D$2+A20-1 -> 46404 | C20: =ROUND($B$2*(1-A20/$F$2),1) -> 0 | D20: =$B$2-SUMIFS($J$27:$J$31,$L$27:$L$31,"<="&A20) -> 0
A22: Thực tế: cuối mỗi ngày điền số điểm CÒN LẠI của sprint vào cột E (ô vàng); ô trống không vẽ lên biểu đồ.
A23: Kế hoạch theo WBS: điểm của story trừ dần vào ngày story đó kết thúc theo lịch ở sheet WBS.
H26: Story | I26: Tên story | J26: Điểm | K26: Kết thúc KH | L26: Ngày thứ (KH)
H27: =LEFT(WBS!C100,4) -> PB22 | I27: =MID(WBS!C100,8,200) -> Khách hàng theo dõi hành trình đơn hàng | J27: =WBS!E100 -> 5 | K27: =WBS!I100 -> 46393 | L27: =K27-$D$2+1 -> 3
H28: =LEFT(WBS!C104,4) -> PB24 | I28: =MID(WBS!C104,8,200) -> Giao tận nơi, xác nhận đã giao theo phiếu | J28: =WBS!E104 -> 3 | K28: =WBS!I104 -> 46394 | L28: =K28-$D$2+1 -> 4
H29: =LEFT(WBS!C108,4) -> PB25 | I29: =MID(WBS!C108,8,200) -> Báo giao thất bại và hoàn hàng | J29: =WBS!E108 -> 3 | K29: =WBS!I108 -> 46398 | L29: =K29-$D$2+1 -> 8
H30: =LEFT(WBS!C112,4) -> PB26 | I30: =MID(WBS!C112,8,200) -> Tra cứu đơn hàng | J30: =WBS!E112 -> 3 | K30: =WBS!I112 -> 46399 | L30: =K30-$D$2+1 -> 9
H31: =LEFT(WBS!C116,4) -> PB27 | I31: =MID(WBS!C116,8,200) -> Báo cáo thống kê | J31: =WBS!E116 -> 3 | K31: =WBS!I116 -> 46401 | L31: =K31-$D$2+1 -> 11
